---
title: 8-1. 调试与异常
date: 2023-05-14
---
## Ⅰ. 代码计时
```js
console.time("test");//开启计时器test

{
    要测试的代码块
}

console.Endtime("test");//结束计时器test;将打印经历的时间
```


## Ⅱ. try...catch
#### 1. 异常的捕获
```js
try{
    code...//可能出现异常的代码
}catch(e){ //e==自定义的异常信息
    code...//出现异常后执行的代码
}

//示例
try{
  a++;
}catch(e){ 
  console.log('error:'+e);  //error:ReferenceError: a is not defined
}
```

#### 2. throw：直接抛出异常
e是异常信息，如果未自己抛出异常，e就是系统异常信息，如果自己抛出了异常，e就是抛出的异常信息。
```js
try{
    code...//可能出现异常的代码
    throw new Error('出错了'); //Error:出错了
    throw '出错了'// 没有Error，直接输出：出错了
}catch(e){ //e==自定义的异常信息
    code...//出现异常后执行的代码
}

//示例
try{
    let a = 10;
    if(a<18){
        throw 'a不能小于18'; //也可以 throw new Error(...)
    }else(a>100){
        throw 'a不能大于100';
    }else(isNaN(a)){
        throw 'a是非法的值'
    }else{
        throw '未定义a'
    }
}catch(e){
    consoel.log('error:'+e);
}
```

#### 3. try...catch...finally
无论是否出错，都会执行finally语句。

```js
try{
    throw 'this is a error';
}catch(e){
    console.log('error:'+e);
}finally{
    console.log('hello'); //该行无论是否抛出异常都会执行。
}
```
省略catch，没出错的话，同上，如果出错，finally处的代码除了会正常执行外，还会自动报错。

#### 4. 总结
- 如果try块中抛出错误，那么try块中错误抛出语句后面的其他语句均不会执行；
- 不管try块中是否抛出错误，finally块语句一定会被执行；
- 内层try块抛出的错误会被对应内层的catch块捕获，如果不存在对应的内层catch块，那么会被抛到上一层，被上一层的catch块捕获，如果还没有被捕获，那么继续抛到上一层，直到最外层。


















